<?xml version="1.0"?>
<robot xmlns:xacro="http://www.ros.org/wiki/xacro"  name="robot">

    <!-- include file that contains material tags -->
    <xacro:include filename="robot_colors.xacro" />

    <!-- include file that contains inertial macros -->
    <xacro:include filename="inertial_macros.xacro" />

    <!-- BASE LINK  -->
    <link name="base_link">

    </link>

    <!-- BASE_FOOTPRINT LINK -->

    <joint name="base_footprint_joint" type="fixed">
        <parent link="base_link"/>
        <child link="base_footprint"/>
        <origin xyz="0 0 0" rpy="0 0 0"/>
    </joint>

    <link name="base_footprint">
    </link>

    <!-- CHASSIS LINK -->
    <joint name="chassis_joint" type="fixed">
        <parent link="base_link"/>
        <child link="chassis"/>
        <origin xyz="-0.1 0.0 0.0" rpy="0.0 0.0 0.0"/>
    </joint>

    <link name="chassis">
        <visual>
            <origin xyz="-0.04 0.0 0.115" rpy="0.0 0.0 0.0"/>
            <geometry>
                <box size="0.46 0.46 0.23"/>
            </geometry>
            <material name="white"/>
        </visual>

        <collision>
            <origin xyz="-0.04 0.0 0.115" rpy="0.0 0.0 0.0"/>
            <geometry>
                <box size="0.46 0.46 0.23"/>
            </geometry>
        </collision>

        <xacro:inertial_box mass="10.319" x="0.46" y="0.46" z="0.3">
            <origin xyz="-0.14743 -0.00064615 0.027414" rpy="0.0 0.0 0.0"/>
        </xacro:inertial_box>
    </link>

    <gazebo reference="chassis">
        <material>Gazebo/White</material>
    </gazebo>

    <!-- LEFT WHEEL LINK -->
    <joint name="left_wheel_joint" type="continuous">
        <parent link="base_link"/>
        <child link="left_wheel"/>
        <origin xyz="0 0.25 0" rpy="${pi/2} 0 0"/>
        <axis xyz="0.0 0.0 1.0"/>
    </joint>
    
    <link name="left_wheel">
    <visual>
        <geometry>
            <cylinder radius="0.083" length="0.04"/>
        </geometry>
        <material name="blue"/>
    </visual>

    <collision>
        <origin xyz="0.0 0.0 0.0" rpy="0.0 0.0 0.0"/>
        <geometry>
            <sphere radius="0.083"/>
        </geometry>
    </collision>

    <xacro:inertial_cylinder mass="0.454027315" length="0.4" radius="0.083">
    <origin xyz="0.0 0.0 0.0" rpy="0.0 0.0 0.0"/>
    </xacro:inertial_cylinder>
    </link>

    <gazebo reference="left_wheel">
        <material>Gazebo/Blue</material>
    </gazebo>
    
    <!-- RIGHT WHEEL LINK -->
    <joint name="right_wheel_joint" type="continuous">
        <parent link="base_link"/>
        <child link="right_wheel"/>
        <origin xyz="0 -0.25 0" rpy="${pi/2} 0 0"/>
        <axis xyz="0.0 0.0 -1.0"/>
    </joint>
    
    <link name="right_wheel">
    <visual>
        <geometry>
            <cylinder radius="0.083" length="0.04"/>
        </geometry>
        <material name="blue"/>
    </visual>

    <collision>
        <geometry>
            <sphere radius="0.083"/>
        </geometry>
    </collision>

    <xacro:inertial_cylinder mass="0.454027315" length="0.4" radius="0.083">
    <origin xyz="0.0 0.0 0.0" rpy="0.0 0.0 0.0"/>
    </xacro:inertial_cylinder>
    </link>

    <gazebo reference="right_wheel">
        <material>Gazebo/Blue</material>
    </gazebo>

    <!-- CASTER WHEEL -->
    <joint name="caster_wheel_joint" type="fixed">
        <parent link="chassis"/>
        <child link="caster_wheel"/>
        <origin xyz="-.3 0.0 0.0" rpy="0.0 0.0 0.0"/>
    </joint>

    <link name="caster_wheel">
        <visual>
            <geometry>
                <sphere radius="0.083"/>
            </geometry>
            <material name="orange" />
        </visual>

        <collision>
            <geometry>
                <sphere radius="0.083"/>
            </geometry>
        </collision>

        <xacro:inertial_sphere mass="0.3" radius="0.083">
        <origin xyz="0.0 0.0 0.0" rpy="0.0 0.0 0.0"/>
        </xacro:inertial_sphere>
    </link>

    <gazebo reference="caster_wheel">
        <material>Gazebo/Orange</material>
        <mu1 value="0.001"/>
        <mu2 value="0.001"/>
    </gazebo>

</robot>