<?xml version="1.0" encoding="utf-8"?>
<!-- This URDF was automatically created by SolidWorks to URDF Exporter! Originally created by Stephen Brawner (brawner@gmail.com) 
     Commit Version: 1.6.0-4-g7f85cfe  Build Version: 1.6.7995.38578
     For more information, please see http://wiki.ros.org/sw_urdf_exporter -->
<robot
  name="Shared_Assembly_Robot_URDF">
<link name="base_footprint">
    <visual>
        <origin xyz="0 0 0" rpy="0 0 0" />
        <geometry>
            <box size="0.001 0.001 0.001" />
        </geometry>
    </visual>
</link>

<joint name="base_footprint_joint" type="fixed">
    <origin xyz="0 0 0.001" rpy="0 0 0" />
    <parent link="base_footprint"/>
    <child link="base_link" />
</joint>

  <link
    name="base_link">
    <inertial>
      <origin
        xyz="-0.14743 -0.00064615 0.027414"
        rpy="0 0 0" />
      <mass
        value="10.319" />
      <inertia
        ixx="0.14128"
        ixy="-1.02E-07"
        ixz="-0.0013572"
        iyy="0.14302"
        iyz="6.92E-08"
        izz="0.27183" />
    </inertial>
    <visual>
      <origin
        xyz="0 0 0"
        rpy="0 0 0" />
      <geometry>
        <mesh
          filename="package://my_bot/urdf/meshes/visual/base_link.STL" />
      </geometry>
      <material
        name="">
        <color
          rgba="1 0 0 1" />
      </material>
    </visual>
    <collision>
      <origin
        xyz="0 0 0"
        rpy="0 0 0" />
      <geometry>
        <mesh
          filename="package://my_bot/urdf/meshes/visual/base_link.STL" />
      </geometry>
    </collision>
  </link>
  <link
    name="right_wheel">
    <inertial>
      <origin
        xyz="-3.13E-08 1.67E-07 0.01837713"
        rpy="0 0 0" />
      <mass
        value="0.454027315" />
      <inertia
        ixx="0.00120506"
        ixy="-6.74E-09"
        ixz="-2.65E-10"
        iyy="0.001205041"
        iyz="7.37E-10"
        izz="0.002290365" />
    </inertial>
    <visual>
      <origin
        xyz="0 0 0"
        rpy="0 0 0" />
      <geometry>
        <mesh
          filename="package://my_bot/urdf/meshes/visual/right_wheel.STL" />
      </geometry>
      <material
        name="">
        <color
          rgba="1 0 0 1" />
      </material>
    </visual>
    <collision>
      <origin
        xyz="0 0 0"
        rpy="0 0 0" />
      <geometry>
        <mesh
          filename="package://my_bot/urdf/meshes/visual/right_wheel.STL" />
      </geometry>
    </collision>
  </link>
  <joint
    name="rightwheel"
    type="continuous">
    <origin
      xyz="0 -0.2881 -0.06135"
      rpy="-1.5708 0 0" />
    <parent
      link="base_link" />
    <child
      link="right_wheel" />
    <axis
      xyz="0 0 1" />
    <limit
      effort="10"
      velocity="10" />
  </joint>
  <link
    name="left_wheel">
    <inertial>
      <origin
        xyz="2.99E-08 1.64E-07 -0.018377129"
        rpy="0 0 0" />
      <mass
        value="0.454027333" />
      <inertia
        ixx="0.00120506"
        ixy="6.67E-09"
        ixz="-2.51E-10"
        iyy="0.001205041"
        iyz="-7.22E-10"
        izz="0.002290365" />
    </inertial>
    <visual>
      <origin
        xyz="0 0 0"
        rpy="0 0 0" />
      <geometry>
        <mesh
          filename="package://my_bot/urdf/meshes/visual/left_wheel.STL" />
      </geometry>
      <material
        name="">
        <color
          rgba="0.752941176470588 0.752941176470588 0.752941176470588 1" />
      </material>
    </visual>
    <collision>
      <origin
        xyz="0 0 0"
        rpy="0 0 0" />
      <geometry>
        <mesh
          filename="package://my_bot/urdf/meshes/visual/left_wheel.STL" />
      </geometry>
    </collision>
  </link>
  <joint
    name="leftwheel"
    type="continuous">
    <origin
      xyz="0 0.2881 -0.06135"
      rpy="-1.5708 0 0" />
    <parent
      link="base_link" />
    <child
      link="left_wheel" />
    <axis
      xyz="0 0 -1" />
    <limit
      effort="10"
      velocity="10" />
  </joint>
  <link
    name="right_caster">
    <inertial>
      <origin
        xyz="-0.00189288936391879 -0.00189303217564021 -0.0154486692656115"
        rpy="0 0 0" />
      <mass
        value="0.201926777784479" />
      <inertia
        ixx="0.000122320156904671"
        ixy="-7.44295460927258E-06"
        ixz="-1.34595075717568E-05"
        iyy="0.000122320567060589"
        iyz="-1.34595571117696E-05"
        izz="0.000137634108009547" />
    </inertial>
    <visual>
      <origin
        xyz="0 0 0"
        rpy="0 0 0" />
      <geometry>
        <mesh
          filename="package://my_bot/urdf/meshes/visual/right_caster.STL" />
      </geometry>
      <material
        name="">
        <color
          rgba="0.898039215686275 0.917647058823529 0.929411764705882 1" />
      </material>
    </visual>
    <collision>
      <origin
        xyz="0 0 0"
        rpy="0 0 0" />
      <geometry>
        <mesh
          filename="package://my_bot/urdf/meshes/visual/right_caster.STL" />
      </geometry>
    </collision>
  </link>
  <joint
    name="rightcaster"
    type="continuous">
    <origin
      xyz="-0.31085 -0.17225 -0.048509"
      rpy="0 0 0" />
    <parent
      link="base_link" />
    <child
      link="right_caster" />
    <axis
      xyz="0 0 1" />
    <limit
      effort="10"
      velocity="10" />
  </joint>
  <link
    name="right_caster_wheel">
    <inertial>
      <origin
        xyz="0 0 -2.77555756156289E-17"
        rpy="0 0 0" />
      <mass
        value="0.0952572284399531" />
      <inertia
        ixx="3.95975514183799E-05"
        ixy="-2.23373147103173E-20"
        ixz="-8.05917790634335E-06"
        iyy="3.15383735120366E-05"
        iyz="2.46467311777879E-20"
        izz="3.95975514183799E-05" />
    </inertial>
    <visual>
      <origin
        xyz="0 0 0"
        rpy="0 0 0" />
      <geometry>
        <mesh
          filename="package://my_bot/urdf/meshes/visual/right_caster_wheel.STL" />
      </geometry>
      <material
        name="">
        <color
          rgba="0.752941176470588 0.752941176470588 0.752941176470588 1" />
      </material>
    </visual>
    <collision>
      <origin
        xyz="0 0 0"
        rpy="0 0 0" />
      <geometry>
        <mesh
          filename="package://my_bot/urdf/meshes/visual/right_caster_wheel.STL" />
      </geometry>
    </collision>
  </link>
  <joint
    name="rightcasterwheel"
    type="continuous">
    <origin
      xyz="-0.020116 -0.020116 -0.066675"
      rpy="-1.5708 0 0" />
    <parent
      link="right_caster" />
    <child
      link="right_caster_wheel" />
    <axis
      xyz="-0.70711 0 0.70711" />
    <limit
      effort="10"
      velocity="10" />
  </joint>
  <link
    name="left_caster">
    <inertial>
      <origin
        xyz="-0.0018930326533278 0.00189288874338733 -0.0154486695307401"
        rpy="0 0 0" />
      <mass
        value="0.201926785403223" />
      <inertia
        ixx="0.000122320571002746"
        ixy="7.44295463657139E-06"
        ixz="-1.34595580196749E-05"
        iyy="0.000122320160007248"
        iyz="1.34595064611714E-05"
        izz="0.000137634115077322" />
    </inertial>
    <visual>
      <origin
        xyz="0 0 0"
        rpy="0 0 0" />
      <geometry>
        <mesh
          filename="package://my_bot/urdf/meshes/visual/left_caster.STL" />
      </geometry>
      <material
        name="">
        <color
          rgba="0.898039215686275 0.917647058823529 0.929411764705882 1" />
      </material>
    </visual>
    <collision>
      <origin
        xyz="0 0 0"
        rpy="0 0 0" />
      <geometry>
        <mesh
          filename="package://my_bot/urdf/meshes/visual/left_caster.STL" />
      </geometry>
    </collision>
  </link>
  <joint
    name="leftcaster"
    type="continuous">
    <origin
      xyz="-0.31085 0.17225 -0.048509"
      rpy="0 0 0" />
    <parent
      link="base_link" />
    <child
      link="left_caster" />
    <axis
      xyz="0 0 1" />
    <limit
      effort="10"
      velocity="10" />
  </joint>
  <link
    name="left_caster_wheel">
    <inertial>
      <origin
        xyz="-5.55111512312578E-17 1.38777878078145E-17 2.77555756156289E-17"
        rpy="0 0 0" />
      <mass
        value="0.0952572284399531" />
      <inertia
        ixx="3.95975514183799E-05"
        ixy="-2.87324106914176E-21"
        ixz="8.05917790634335E-06"
        iyy="3.15383735120366E-05"
        iyz="-5.9032804633219E-21"
        izz="3.95975514183799E-05" />
    </inertial>
    <visual>
      <origin
        xyz="0 0 0"
        rpy="0 0 0" />
      <geometry>
        <mesh
          filename="package://my_bot/urdf/meshes/visual/left_caster_wheel.STL" />
      </geometry>
      <material
        name="">
        <color
          rgba="0.752941176470588 0.752941176470588 0.752941176470588 1" />
      </material>
    </visual>
    <collision>
      <origin
        xyz="0 0 0"
        rpy="0 0 0" />
      <geometry>
        <mesh
          filename="package://my_bot/urdf/meshes/visual/left_caster_wheel.STL" />
      </geometry>
    </collision>
  </link>
  <joint
    name="leftcasterwheel"
    type="continuous">
    <origin
      xyz="-0.020116 0.020116 -0.066675"
      rpy="-1.5708 0 0" />
    <parent
      link="left_caster" />
    <child
      link="left_caster_wheel" />
    <axis
      xyz="0.70711 0 0.70711" />
    <limit
      effort="10"
      velocity="10" />
  </joint>
</robot>
